#VRML_SIM R2022a utf8
WorldInfo {
}
Viewpoint {
  orientation -0.20307950333821814 0.09436274798944601 0.9746047337848217 2.7218029917213973
  position 2.243702147874689 -0.9695152147915711 1.129383910696952
  follow "my_robot"
}
TexturedBackground {
}
TexturedBackgroundLight {
}
CircleArena {
}
WoodenBox {
  translation 0.0314627 0.482227 0.11
  rotation 0.9831056944488314 0.1294279597735375 0.1294279597735375 1.58784
  name "wooden box(3)"
  size 0.1 0.2 0.1
}
WoodenBox {
  translation -0.661555 -0.138272 0.109997
  rotation 0.9831056944488314 0.1294279597735375 0.1294279597735375 1.58784
  name "wooden box(4)"
  size 0.1 0.2 0.15
}
WoodenBox {
  translation -0.17 -0.56 0.06
  rotation -0.9351130202419243 0.25056300542381216 0.25056300542381216 -1.6378353071795866
  name "wooden box(1)"
  size 0.1 0.1 0.2
}
WoodenBox {
  translation 0.695039 0.401227 0.0599976
  rotation 0.9831056944488314 0.1294279597735375 0.1294279597735375 1.58784
  name "wooden box(2)"
  size 0.2 0.15 0.3
}
WoodenBox {
  translation 0.42 -0.11 0.06
  rotation 1 0 0 1.5707963267948966
  size 0.1 0.1 0.1
}
Robot {
  children [
    HingeJoint {
      jointParameters HingeJointParameters {
        axis 0 1 0
        anchor 0 0 0.025
      }
      device [
        RotationalMotor {
          name "left wheel motor"
        }
      ]
      endPoint Solid {
        translation 0 0.045 0.025
        rotation 0 1 0 0
        children [
          DEF WHEEL Transform {
            rotation 1 0 0 1.5707996938995747
            children [
              Shape {
                appearance PBRAppearance {
                  baseColor 1 0 0
                  roughness 1
                  metalness 0
                }
                geometry Cylinder {
                  height 0.01
                  radius 0.025
                }
              }
            ]
          }
        ]
        name "left wheel"
        boundingObject USE WHEEL
        physics Physics {
        }
      }
    }
    HingeJoint {
      jointParameters HingeJointParameters {
        axis 0 1 0
        anchor 0 0 0.025
      }
      device [
        RotationalMotor {
          name "right wheel motor"
        }
      ]
      endPoint Solid {
        translation 0 -0.045 0.025
        rotation 0 1 0 0
        children [
          USE WHEEL
        ]
        name "right wheel"
        boundingObject USE WHEEL
        physics Physics {
        }
      }
    }
    Transform {
      translation 0 0 0.0415
      children [
        Shape {
          appearance PBRAppearance {
            baseColor 0 0 1
            roughness 1
            metalness 0
          }
          geometry DEF BODY Cylinder {
            height 0.08
            radius 0.045
          }
        }
      ]
    }
    DistanceSensor {
      translation 0.042 0.02 0.063
      rotation 0 0 1 0.5236003061004253
      children [
        DEF SENSOR Transform {
          rotation 0 1 0 1.5708
          children [
            Shape {
              appearance PBRAppearance {
                baseColor 1 1 0
                roughness 1
                metalness 0
              }
              geometry Cylinder {
                height 0.004
                radius 0.008
              }
            }
          ]
        }
      ]
      name "ds0"
      lookupTable [
        0 1020 0
        0.05 1020 0
        0.15 0 0
      ]
      numberOfRays 2
      aperture 1
    }
    DistanceSensor {
      translation 0.042 -0.02 0.063
      rotation 0 0 1 -0.5235996938995747
      children [
        USE SENSOR
      ]
      name "ds1"
      lookupTable [
        0 1020 0
        0.05 1020 0
        0.15 0 0
      ]
      numberOfRays 2
      aperture 1
    }
  ]
  name "my_robot"
  boundingObject Transform {
    translation 0 0 0.0415
    children [
      USE BODY
    ]
  }
  physics Physics {
  }
  controller "<extern>"
}
