#VRML_SIM R2022a utf8
WorldInfo {
}
Viewpoint {
  orientation -0.25241085175292693 -0.04984047733816128 0.966335701884219 3.24321607247008
  position 2.022269178815053 0.39191755758686353 1.1889623289877775
  follow "my_robot"
}
TexturedBackground {
}
TexturedBackgroundLight {
}
CircleArena {
}
Robot {
  rotation 0 0 1 1.5708
  children [
    HingeJoint {
      jointParameters HingeJointParameters {
        axis 0 1 0
        anchor 0 0 0.025
      }
      device [
        RotationalMotor {
          name "left wheel motor"
        }
      ]
      endPoint Solid {
        translation 0 0.045 0.025
        rotation 0 1 0 0
        children [
          DEF WHEEL Transform {
            rotation 1 0 0 1.5707996938995747
            children [
              Shape {
                appearance PBRAppearance {
                  baseColor 1 0 0
                  roughness 1
                  metalness 0
                }
                geometry Cylinder {
                  height 0.01
                  radius 0.025
                }
              }
            ]
          }
        ]
        name "left wheel"
        boundingObject USE WHEEL
        physics Physics {
        }
      }
    }
    HingeJoint {
      jointParameters HingeJointParameters {
        axis 0 1 0
        anchor 0 0 0.025
      }
      device [
        RotationalMotor {
          name "right wheel motor"
        }
      ]
      endPoint Solid {
        translation 0 -0.045 0.025
        rotation 0 1 0 0
        children [
          USE WHEEL
        ]
        name "right wheel"
        boundingObject USE WHEEL
        physics Physics {
        }
      }
    }
    Transform {
      translation 0 0 0.0415
      children [
        Shape {
          appearance PBRAppearance {
            baseColor 0 0 1
            roughness 1
            metalness 0
          }
          geometry DEF BODY Cylinder {
            height 0.08
            radius 0.045
          }
        }
      ]
    }
    DistanceSensor {
      translation 0.042 0.02 0.063
      rotation 0 0 1 0.5236003061004253
      children [
        DEF SENSOR Transform {
          rotation 0 1 0 1.5708
          children [
            Shape {
              appearance PBRAppearance {
                baseColor 1 1 0
                roughness 1
                metalness 0
              }
              geometry Cylinder {
                height 0.004
                radius 0.008
              }
            }
          ]
        }
      ]
      name "ds0"
      lookupTable [
        0 1020 0
        0.05 1020 0
        0.15 0 0
      ]
      numberOfRays 2
      aperture 1
    }
    DistanceSensor {
      translation 0.042 -0.02 0.063
      rotation 0 0 1 -0.5235996938995747
      children [
        USE SENSOR
      ]
      name "ds1"
      lookupTable [
        0 1020 0
        0.05 1020 0
        0.15 0 0
      ]
      numberOfRays 2
      aperture 1
    }
  ]
  name "RBT_1"
  boundingObject Transform {
    translation 0 0 0.0415
    rotation 0 0 1 1.57
    children [
      USE BODY
    ]
  }
  physics Physics {
  }
  controller "<extern>"
}
Robot {
  translation -5.19723e-15 0.52 0
  rotation 0 0 1 -1.5707953071795862
  children [
    HingeJoint {
      jointParameters HingeJointParameters {
        axis 0 1 0
        anchor 0 0 0.025
      }
      device [
        RotationalMotor {
          name "left wheel motor"
        }
      ]
      endPoint Solid {
        translation 0 0.045 0.025
        rotation 0 1 0 0
        children [
          DEF WHEEL Transform {
            rotation 1 0 0 1.5707996938995747
            children [
              Shape {
                appearance PBRAppearance {
                  baseColor 1 0 0
                  roughness 1
                  metalness 0
                }
                geometry Cylinder {
                  height 0.01
                  radius 0.025
                }
              }
            ]
          }
        ]
        name "left wheel"
        boundingObject USE WHEEL
        physics Physics {
        }
      }
    }
    HingeJoint {
      jointParameters HingeJointParameters {
        axis 0 1 0
        anchor 0 0 0.025
      }
      device [
        RotationalMotor {
          name "right wheel motor"
        }
      ]
      endPoint Solid {
        translation 0 -0.045 0.025
        rotation 0 1 0 0
        children [
          USE WHEEL
        ]
        name "right wheel"
        boundingObject USE WHEEL
        physics Physics {
        }
      }
    }
    Transform {
      translation 0 0 0.0415
      children [
        Shape {
          appearance PBRAppearance {
            baseColor 0 0 1
            roughness 1
            metalness 0
          }
          geometry DEF BODY Cylinder {
            height 0.08
            radius 0.045
          }
        }
      ]
    }
    DistanceSensor {
      translation 0.042 0.02 0.063
      rotation 0 0 1 0.5236003061004253
      children [
        DEF SENSOR Transform {
          rotation 0 1 0 1.5708
          children [
            Shape {
              appearance PBRAppearance {
                baseColor 1 1 0
                roughness 1
                metalness 0
              }
              geometry Cylinder {
                height 0.004
                radius 0.008
              }
            }
          ]
        }
      ]
      name "ds0"
      lookupTable [
        0 1020 0
        0.05 1020 0
        0.15 0 0
      ]
      numberOfRays 2
      aperture 1
    }
    DistanceSensor {
      translation 0.042 -0.02 0.063
      rotation 0 0 1 -0.5235996938995747
      children [
        USE SENSOR
      ]
      name "ds1"
      lookupTable [
        0 1020 0
        0.05 1020 0
        0.15 0 0
      ]
      numberOfRays 2
      aperture 1
    }
  ]
  name "RBT_2"
  boundingObject Transform {
    translation 0 0 0.0415
    rotation 0 0 1 1.57
    children [
      USE BODY
    ]
  }
  physics Physics {
  }
  controller "<extern>"
}
WoodenBox {
  translation 0.5 0 0.052
  rotation 0 0 1 -0.523595307179586
  name "wooden box(1)"
  size 0.1 0.1 0.1
  mass 8
}
WoodenBox {
  translation -0.214979 -0.118372 0.052
  rotation 0 0 1 0.785402
  name "wooden box(2)"
  size 0.1 0.3 0.1
  mass 8
}
WoodenBox {
  translation -0.0587212 -0.346591 0.052
  rotation 0 0 -1 0.261797
  name "wooden box(3)"
  size 0.1 0.2 0.1
  mass 13
}
WoodenBox {
  translation -0.265769 -0.766163 0.102
  rotation 0 0 1 0.785401
  name "wooden box(4)"
  size 0.2 0.2 0.2
  mass 15
}
WoodenBox {
  translation 0.179706 0.79654 0.102
  rotation 0 0 1 -0.261795307179586
  name "wooden box(5)"
  size 0.2 0.2 0.2
  mass 15
}
WoodenBox {
  translation -0.817307 -0.214625 0.052
  rotation 0 0 1 -0.785395307179586
  name "wooden box(6)"
  size 0.1 0.2 0.1
  mass 10
}
WoodenBox {
  translation -0.708145 -0.0197317 0.052
  rotation 0 0 -1 0.261797
  name "wooden box(7)"
  size 0.1 0.2 0.1
  mass 10
}
WoodenBox {
  translation -0.83852 -0.235838 0.155
  rotation 0 0 1 -0.785395307179586
  name "wooden box(8)"
  size 0.1 0.1 0.1
  mass 5
}
WoodenBox {
  translation 0.328439 0.750598 0.052
  rotation 0 0 -1 0.261797
  name "wooden box(9)"
  size 0.1 0.2 0.1
  mass 15
}
